<robot name='robot'>

	<material name='gray'>
		<color rgba='0.89 0.46 0.02 1'/>
	</material>

	<link name='base'>
		<visual>
			<geometry>
				<box size='0.5 0.5 0.1'/>
			</geometry>
			<material name='gray'/>
			<origin xyz="0 0 0.05"/>
		</visual>
	</link>

	<link name='elevator'>
		<visual>
			<geometry>
				<cylinder length='1' radius='0.02'/>
			</geometry>
			<material name='gray'/>
			<origin xyz="0 0 0.6"/>
		</visual>
	</link>

	<joint name='base-to-elevator' type="fixed">
     	<parent link="base"/>
   		<child link="elevator"/>
     	<origin xyz="0 0 0"/>
   	</joint>

	<link name='base-rotator'>
		<visual>
			<geometry>
				<cylinder length='0.05' radius='0.1'/>
			</geometry>
			<material name='gray'/>
			<origin rpy='0 0 0' xyz="0 0 0"/>
		</visual>
	</link>

	<joint name="elevator-to-base-rotator" type="prismatic">
		<parent link="elevator"/>
		<child link="base-rotator"/>
		<limit effort="1000.0" lower="0" upper="0.8" velocity="10"/>
		<origin rpy="0 0 0" xyz="0 0 0.125"/>
      	<axis xyz="0 0 1"/>
	</joint>

	<link name='arm'>
		<visual>
			<geometry>
				<cylinder radius='0.03' length='1'/>
			</geometry>
			<material name='gray'/>
			<origin rpy='0 1.57 0' xyz="0.5 0 0"/>
		</visual>
	</link>

  	<joint name="base-rotator-to-arm" type="revolute">
	    <axis xyz="0 0 1"/>
	    <limit effort="1000.0" lower="0.0" upper="6.28" velocity="0.5"/>
	    <origin rpy="0 0 0" xyz="0 0 0"/>
	    <parent link="base-rotator"/>
	    <child link="arm"/>
  	</joint>

  	<link name='arm-rotator'>
		<visual>
			<geometry>
				<sphere radius='0.05'/>
			</geometry>
			<material name='gray'/>
			<origin rpy='0 0 0' xyz="0 0 0"/>
		</visual>
	</link>

	<joint name="arm-to-arm-rotator" type="fixed">
	    <origin rpy="0 0 0" xyz="1 0 0"/>
	    <parent link="arm"/>
	    <child link="arm-rotator"/>
  	</joint>

  	<link name='manipulator'>
		<visual>
			<geometry>
				<cylinder length='0.2' radius='0.02'/>
			</geometry>
			<material name='gray'/>
			<origin rpy='0 1.57 0' xyz="0.1 0 0"/>
		</visual>
	</link>

	<joint name="arm-rotator-to-manipulator" type="revolute">
		<axis xyz='0 0 1'/>
		<limit effort="1000.0" lower="-1.57" upper="1.57" velocity="0.5"/>
	    <origin rpy="0 0 0" xyz="0 0 0"/>
	    <parent link="arm-rotator"/>
	    <child link="manipulator"/>
  	</joint>


</robot>
