<robot name="r2d2">

  <link name="stand">
    <visual>
      <origin xyz="0 0 0" rpy="1.57 0 0" />
      <geometry>
        <cylinder radius="0.005" length=".9" />
      </geometry>
      <material name="white">
        <color rgba="1 1 1 1"/>
      </material>
    </visual>

  </link>

  <link name="body">

    <visual>
      <origin xyz="0 0 -0.2" />
      <geometry>
        <cylinder radius=".20" length=".6"/>
      </geometry>
      <material name="white"/>
    </visual>

  </link>

  <joint name="tilt" type="revolute">
    <parent link="stand"/>
    <child link="body"/>
    <origin xyz="0 0 0" rpy="0 0 0" />
    <axis xyz="0 1 0" />
    <limit upper="0" lower="-.5" effort="10" velocity="10" />
  </joint>



</robot>
